Unhandled exception in thread started by <function check_errors.<locals>.wrapper at 0x7f190ed6fd08>
Traceback (most recent call last):
  File "/home/cloud/django/myvenv/lib64/python3.6/site-packages/django/utils/autoreload.py", line 226, in wrapper
    fn(*args, **kwargs)
  File "/home/cloud/django/myvenv/lib64/python3.6/site-packages/django/core/management/commands/runserver.py", line 121, in inner_run
    self.check(display_num_errors=True)
  File "/home/cloud/django/myvenv/lib64/python3.6/site-packages/django/core/management/base.py", line 374, in check
    include_deployment_checks=include_deployment_checks,
  File "/home/cloud/django/myvenv/lib64/python3.6/site-packages/django/core/management/base.py", line 361, in _run_checks
    return checks.run_checks(**kwargs)
  File "/home/cloud/django/myvenv/lib64/python3.6/site-packages/django/core/checks/registry.py", line 81, in run_checks
    new_errors = check(app_configs=app_configs)
  File "/home/cloud/django/myvenv/lib64/python3.6/site-packages/django/core/checks/urls.py", line 14, in check_url_config
    return check_resolver(resolver)
  File "/home/cloud/django/myvenv/lib64/python3.6/site-packages/django/core/checks/urls.py", line 24, in check_resolver
    for pattern in resolver.url_patterns:
  File "/home/cloud/django/myvenv/lib64/python3.6/site-packages/django/utils/functional.py", line 35, in __get__
    res = instance.__dict__[self.name] = self.func(instance)
  File "/home/cloud/django/myvenv/lib64/python3.6/site-packages/django/urls/resolvers.py", line 313, in url_patterns
    patterns = getattr(self.urlconf_module, "urlpatterns", self.urlconf_module)
  File "/home/cloud/django/myvenv/lib64/python3.6/site-packages/django/utils/functional.py", line 35, in __get__
    res = instance.__dict__[self.name] = self.func(instance)
  File "/home/cloud/django/myvenv/lib64/python3.6/site-packages/django/urls/resolvers.py", line 306, in urlconf_module
    return import_module(self.urlconf_name)
  File "/usr/lib64/python3.6/importlib/__init__.py", line 126, in import_module
    return _bootstrap._gcd_import(name[level:], package, level)
  File "<frozen importlib._bootstrap>", line 978, in _gcd_import
  File "<frozen importlib._bootstrap>", line 961, in _find_and_load
  File "<frozen importlib._bootstrap>", line 950, in _find_and_load_unlocked
  File "<frozen importlib._bootstrap>", line 655, in _load_unlocked
  File "<frozen importlib._bootstrap_external>", line 678, in exec_module
  File "<frozen importlib._bootstrap>", line 205, in _call_with_frames_removed
  File "/home/cloud/django/mysite/urls.py", line 21, in <module>
    url(r'', include('blog.urls')),
NameError: name 'include' is not defined
Performing system checks...

[17/Jul/2017 07:33:15] "GET / HTTP/1.1" 200 931
[17/Jul/2017 07:33:17] "GET / HTTP/1.1" 200 931
[17/Jul/2017 07:33:18] "GET / HTTP/1.1" 200 931
[17/Jul/2017 07:34:36] "GET / HTTP/1.1" 200 931
[17/Jul/2017 07:35:28] "GET / HTTP/1.1" 200 931
Performing system checks...

System check identified no issues (0 silenced).
July 17, 2017 - 07:32:04
Django version 1.10.7, using settings 'mysite.settings'
Starting development server at http://192.168.29.87:8000/
Quit the server with CONTROL-C.
[17/Jul/2017 07:36:56] "GET / HTTP/1.1" 200 931
[17/Jul/2017 07:36:58] "GET / HTTP/1.1" 200 931
[17/Jul/2017 07:36:59] "GET / HTTP/1.1" 200 931
[17/Jul/2017 07:37:00] "GET / HTTP/1.1" 200 931
[17/Jul/2017 07:38:28] "GET / HTTP/1.1" 200 314
[17/Jul/2017 07:38:29] "GET / HTTP/1.1" 200 314
[17/Jul/2017 07:38:30] "GET / HTTP/1.1" 200 314
[17/Jul/2017 07:38:31] "GET / HTTP/1.1" 200 314
[17/Jul/2017 07:39:58] "GET / HTTP/1.1" 200 512
[17/Jul/2017 07:42:43] "GET / HTTP/1.1" 200 566
[17/Jul/2017 07:42:43] "GET /static/css/blog.css HTTP/1.1" 200 62
[17/Jul/2017 07:43:29] "GET / HTTP/1.1" 200 566
[17/Jul/2017 07:43:29] "GET /static/css/blog.css HTTP/1.1" 200 90
[17/Jul/2017 07:44:41] "GET / HTTP/1.1" 200 712
[17/Jul/2017 07:44:41] "GET /static/css/blog.css HTTP/1.1" 304 0
[17/Jul/2017 07:45:08] "GET / HTTP/1.1" 200 712
[17/Jul/2017 07:45:08] "GET /static/css/blog.css HTTP/1.1" 200 792
[17/Jul/2017 07:46:39] "GET / HTTP/1.1" 200 977
[17/Jul/2017 07:46:39] "GET /static/css/blog.css HTTP/1.1" 304 0
[17/Jul/2017 07:48:36] "GET / HTTP/1.1" 200 1010
[17/Jul/2017 07:48:36] "GET /static/css/blog.css HTTP/1.1" 304 0
[17/Jul/2017 07:50:29] "GET / HTTP/1.1" 200 1010
[17/Jul/2017 07:50:29] "GET /static/css/blog.css HTTP/1.1" 200 792
Not Found: /favicon.ico
[17/Jul/2017 07:50:30] "GET /favicon.ico HTTP/1.1" 404 2109
[17/Jul/2017 07:51:56] "GET / HTTP/1.1" 200 1010
[17/Jul/2017 07:51:56] "GET /static/css/blog.css HTTP/1.1" 200 793
[17/Jul/2017 07:52:07] "GET / HTTP/1.1" 200 1010
[17/Jul/2017 07:52:07] "GET /static/css/blog.css HTTP/1.1" 200 793
[17/Jul/2017 07:52:20] "GET / HTTP/1.1" 200 1010
[17/Jul/2017 07:52:20] "GET /static/css/blog.css HTTP/1.1" 200 794
[17/Jul/2017 07:52:29] "GET / HTTP/1.1" 200 1010
[17/Jul/2017 07:52:30] "GET /static/css/blog.css HTTP/1.1" 200 793
[17/Jul/2017 07:52:42] "GET / HTTP/1.1" 200 1010
[17/Jul/2017 07:52:42] "GET /static/css/blog.css HTTP/1.1" 200 794
[17/Jul/2017 07:52:51] "GET / HTTP/1.1" 200 1010
[17/Jul/2017 07:52:51] "GET /static/css/blog.css HTTP/1.1" 200 794
[17/Jul/2017 07:54:44] "GET / HTTP/1.1" 200 1163
[17/Jul/2017 07:54:44] "GET /static/css/blog.css HTTP/1.1" 304 0
[17/Jul/2017 07:56:01] "GET / HTTP/1.1" 200 1025
[17/Jul/2017 07:56:01] "GET /static/css/blog.css HTTP/1.1" 304 0
[17/Jul/2017 07:57:18] "GET / HTTP/1.1" 200 1025
[17/Jul/2017 07:57:18] "GET /static/css/blog.css HTTP/1.1" 304 0
Internal Server Error: /
Traceback (most recent call last):
  File "/home/cloud/django/myvenv/lib64/python3.6/site-packages/django/template/base.py", line 510, in parse
    compile_func = self.tags[command]
KeyError: 'static'

During handling of the above exception, another exception occurred:

Traceback (most recent call last):
  File "/home/cloud/django/myvenv/lib64/python3.6/site-packages/django/core/handlers/exception.py", line 42, in inner
    response = get_response(request)
  File "/home/cloud/django/myvenv/lib64/python3.6/site-packages/django/core/handlers/base.py", line 187, in _get_response
    response = self.process_exception_by_middleware(e, request)
  File "/home/cloud/django/myvenv/lib64/python3.6/site-packages/django/core/handlers/base.py", line 185, in _get_response
    response = wrapped_callback(request, *callback_args, **callback_kwargs)
  File "/home/cloud/django/blog/views.py", line 7, in post_list
    return render(request, 'blog/post_list.html', {'posts': posts})
  File "/home/cloud/django/myvenv/lib64/python3.6/site-packages/django/shortcuts.py", line 30, in render
    content = loader.render_to_string(template_name, context, request, using=using)
  File "/home/cloud/django/myvenv/lib64/python3.6/site-packages/django/template/loader.py", line 68, in render_to_string
    return template.render(context, request)
  File "/home/cloud/django/myvenv/lib64/python3.6/site-packages/django/template/backends/django.py", line 66, in render
    return self.template.render(context)
  File "/home/cloud/django/myvenv/lib64/python3.6/site-packages/django/template/base.py", line 208, in render
    return self._render(context)
  File "/home/cloud/django/myvenv/lib64/python3.6/site-packages/django/template/base.py", line 199, in _render
    return self.nodelist.render(context)
  File "/home/cloud/django/myvenv/lib64/python3.6/site-packages/django/template/base.py", line 994, in render
    bit = node.render_annotated(context)
  File "/home/cloud/django/myvenv/lib64/python3.6/site-packages/django/template/base.py", line 961, in render_annotated
    return self.render(context)
  File "/home/cloud/django/myvenv/lib64/python3.6/site-packages/django/template/loader_tags.py", line 152, in render
    compiled_parent = self.get_parent(context)
  File "/home/cloud/django/myvenv/lib64/python3.6/site-packages/django/template/loader_tags.py", line 149, in get_parent
    return self.find_template(parent, context)
  File "/home/cloud/django/myvenv/lib64/python3.6/site-packages/django/template/loader_tags.py", line 129, in find_template
    template_name, skip=history,
  File "/home/cloud/django/myvenv/lib64/python3.6/site-packages/django/template/engine.py", line 134, in find_template
    name, template_dirs=dirs, skip=skip,
  File "/home/cloud/django/myvenv/lib64/python3.6/site-packages/django/template/loaders/base.py", line 44, in get_template
    contents, origin, origin.template_name, self.engine,
  File "/home/cloud/django/myvenv/lib64/python3.6/site-packages/django/template/base.py", line 191, in __init__
    self.nodelist = self.compile_nodelist()
  File "/home/cloud/django/myvenv/lib64/python3.6/site-packages/django/template/base.py", line 233, in compile_nodelist
    return parser.parse()
  File "/home/cloud/django/myvenv/lib64/python3.6/site-packages/django/template/base.py", line 512, in parse
    self.invalid_block_tag(token, command, parse_until)
  File "/home/cloud/django/myvenv/lib64/python3.6/site-packages/django/template/base.py", line 574, in invalid_block_tag
    "or load this tag?" % (token.lineno, command)
django.template.exceptions.TemplateSyntaxError: Invalid block tag on line 8: 'static'. Did you forget to register or load this tag?
[17/Jul/2017 08:09:05] "GET / HTTP/1.1" 500 144799
[17/Jul/2017 08:09:28] "GET / HTTP/1.1" 200 1001
[17/Jul/2017 08:09:28] "GET /static/css/blog.css HTTP/1.1" 304 0
[17/Jul/2017 08:10:56] "GET / HTTP/1.1" 200 1001
[17/Jul/2017 08:10:56] "GET /static/css/blog.css HTTP/1.1" 304 0
Internal Server Error: /
Traceback (most recent call last):
  File "/home/cloud/django/myvenv/lib64/python3.6/site-packages/django/core/handlers/exception.py", line 42, in inner
    response = get_response(request)
  File "/home/cloud/django/myvenv/lib64/python3.6/site-packages/django/core/handlers/base.py", line 187, in _get_response
    response = self.process_exception_by_middleware(e, request)
  File "/home/cloud/django/myvenv/lib64/python3.6/site-packages/django/core/handlers/base.py", line 185, in _get_response
    response = wrapped_callback(request, *callback_args, **callback_kwargs)
  File "/home/cloud/django/blog/views.py", line 7, in post_list
    return render(request, 'blog/post_list.html', {'posts': posts})
  File "/home/cloud/django/myvenv/lib64/python3.6/site-packages/django/shortcuts.py", line 30, in render
    content = loader.render_to_string(template_name, context, request, using=using)
  File "/home/cloud/django/myvenv/lib64/python3.6/site-packages/django/template/loader.py", line 68, in render_to_string
    return template.render(context, request)
  File "/home/cloud/django/myvenv/lib64/python3.6/site-packages/django/template/backends/django.py", line 66, in render
    return self.template.render(context)
  File "/home/cloud/django/myvenv/lib64/python3.6/site-packages/django/template/base.py", line 208, in render
    return self._render(context)
  File "/home/cloud/django/myvenv/lib64/python3.6/site-packages/django/template/base.py", line 199, in _render
    return self.nodelist.render(context)
  File "/home/cloud/django/myvenv/lib64/python3.6/site-packages/django/template/base.py", line 994, in render
    bit = node.render_annotated(context)
  File "/home/cloud/django/myvenv/lib64/python3.6/site-packages/django/template/base.py", line 961, in render_annotated
    return self.render(context)
  File "/home/cloud/django/myvenv/lib64/python3.6/site-packages/django/template/loader_tags.py", line 174, in render
    return compiled_parent._render(context)
  File "/home/cloud/django/myvenv/lib64/python3.6/site-packages/django/template/base.py", line 199, in _render
    return self.nodelist.render(context)
  File "/home/cloud/django/myvenv/lib64/python3.6/site-packages/django/template/base.py", line 994, in render
    bit = node.render_annotated(context)
  File "/home/cloud/django/myvenv/lib64/python3.6/site-packages/django/template/base.py", line 961, in render_annotated
    return self.render(context)
  File "/home/cloud/django/myvenv/lib64/python3.6/site-packages/django/template/loader_tags.py", line 70, in render
    result = block.nodelist.render(context)
  File "/home/cloud/django/myvenv/lib64/python3.6/site-packages/django/template/base.py", line 994, in render
    bit = node.render_annotated(context)
  File "/home/cloud/django/myvenv/lib64/python3.6/site-packages/django/template/base.py", line 961, in render_annotated
    return self.render(context)
  File "/home/cloud/django/myvenv/lib64/python3.6/site-packages/django/template/defaulttags.py", line 209, in render
    nodelist.append(node.render_annotated(context))
  File "/home/cloud/django/myvenv/lib64/python3.6/site-packages/django/template/base.py", line 961, in render_annotated
    return self.render(context)
  File "/home/cloud/django/myvenv/lib64/python3.6/site-packages/django/template/defaulttags.py", line 439, in render
    url = reverse(view_name, args=args, kwargs=kwargs, current_app=current_app)
  File "/home/cloud/django/myvenv/lib64/python3.6/site-packages/django/urls/base.py", line 91, in reverse
    return force_text(iri_to_uri(resolver._reverse_with_prefix(view, prefix, *args, **kwargs)))
  File "/home/cloud/django/myvenv/lib64/python3.6/site-packages/django/urls/resolvers.py", line 392, in _reverse_with_prefix
    (lookup_view_s, args, kwargs, len(patterns), patterns)
django.urls.exceptions.NoReverseMatch: Reverse for 'post_detail' with arguments '()' and keyword arguments '{'pk': 1}' not found. 0 pattern(s) tried: []
[17/Jul/2017 08:11:54] "GET / HTTP/1.1" 500 155611
Performing system checks...

System check identified no issues (0 silenced).
July 17, 2017 - 07:36:52
Django version 1.10.7, using settings 'mysite.settings'
Starting development server at http://192.168.29.87:8000/
Quit the server with CONTROL-C.
Unhandled exception in thread started by <function check_errors.<locals>.wrapper at 0x7fdbb308bd08>
Traceback (most recent call last):
  File "/home/cloud/django/myvenv/lib64/python3.6/site-packages/django/utils/autoreload.py", line 226, in wrapper
    fn(*args, **kwargs)
  File "/home/cloud/django/myvenv/lib64/python3.6/site-packages/django/core/management/commands/runserver.py", line 121, in inner_run
    self.check(display_num_errors=True)
  File "/home/cloud/django/myvenv/lib64/python3.6/site-packages/django/core/management/base.py", line 374, in check
    include_deployment_checks=include_deployment_checks,
  File "/home/cloud/django/myvenv/lib64/python3.6/site-packages/django/core/management/base.py", line 361, in _run_checks
    return checks.run_checks(**kwargs)
  File "/home/cloud/django/myvenv/lib64/python3.6/site-packages/django/core/checks/registry.py", line 81, in run_checks
    new_errors = check(app_configs=app_configs)
  File "/home/cloud/django/myvenv/lib64/python3.6/site-packages/django/core/checks/urls.py", line 14, in check_url_config
    return check_resolver(resolver)
  File "/home/cloud/django/myvenv/lib64/python3.6/site-packages/django/core/checks/urls.py", line 24, in check_resolver
    for pattern in resolver.url_patterns:
  File "/home/cloud/django/myvenv/lib64/python3.6/site-packages/django/utils/functional.py", line 35, in __get__
    res = instance.__dict__[self.name] = self.func(instance)
  File "/home/cloud/django/myvenv/lib64/python3.6/site-packages/django/urls/resolvers.py", line 313, in url_patterns
    patterns = getattr(self.urlconf_module, "urlpatterns", self.urlconf_module)
  File "/home/cloud/django/myvenv/lib64/python3.6/site-packages/django/utils/functional.py", line 35, in __get__
    res = instance.__dict__[self.name] = self.func(instance)
  File "/home/cloud/django/myvenv/lib64/python3.6/site-packages/django/urls/resolvers.py", line 306, in urlconf_module
    return import_module(self.urlconf_name)
  File "/usr/lib64/python3.6/importlib/__init__.py", line 126, in import_module
    return _bootstrap._gcd_import(name[level:], package, level)
  File "<frozen importlib._bootstrap>", line 978, in _gcd_import
  File "<frozen importlib._bootstrap>", line 961, in _find_and_load
  File "<frozen importlib._bootstrap>", line 950, in _find_and_load_unlocked
  File "<frozen importlib._bootstrap>", line 655, in _load_unlocked
  File "<frozen importlib._bootstrap_external>", line 678, in exec_module
  File "<frozen importlib._bootstrap>", line 205, in _call_with_frames_removed
  File "/home/cloud/django/mysite/urls.py", line 21, in <module>
    url(r'', include('blog.urls')),
  File "/home/cloud/django/myvenv/lib64/python3.6/site-packages/django/conf/urls/__init__.py", line 50, in include
    urlconf_module = import_module(urlconf_module)
  File "/usr/lib64/python3.6/importlib/__init__.py", line 126, in import_module
    return _bootstrap._gcd_import(name[level:], package, level)
  File "<frozen importlib._bootstrap>", line 978, in _gcd_import
  File "<frozen importlib._bootstrap>", line 961, in _find_and_load
  File "<frozen importlib._bootstrap>", line 950, in _find_and_load_unlocked
  File "<frozen importlib._bootstrap>", line 655, in _load_unlocked
  File "<frozen importlib._bootstrap_external>", line 678, in exec_module
  File "<frozen importlib._bootstrap>", line 205, in _call_with_frames_removed
  File "/home/cloud/django/blog/urls.py", line 6, in <module>
    url(r'^post/(?P<pk>\d+)/$', views.post_detail, name='post_detail'),
AttributeError: module 'blog.views' has no attribute 'post_detail'
Performing system checks...

Internal Server Error: /
Traceback (most recent call last):
  File "/home/cloud/django/myvenv/lib64/python3.6/site-packages/django/core/handlers/exception.py", line 42, in inner
    response = get_response(request)
  File "/home/cloud/django/myvenv/lib64/python3.6/site-packages/django/core/handlers/base.py", line 187, in _get_response
    response = self.process_exception_by_middleware(e, request)
  File "/home/cloud/django/myvenv/lib64/python3.6/site-packages/django/core/handlers/base.py", line 185, in _get_response
    response = wrapped_callback(request, *callback_args, **callback_kwargs)
  File "/home/cloud/django/blog/views.py", line 8, in post_list
    return render(request, 'blog/post_list.html', {'posts': posts})
  File "/home/cloud/django/myvenv/lib64/python3.6/site-packages/django/shortcuts.py", line 30, in render
    content = loader.render_to_string(template_name, context, request, using=using)
  File "/home/cloud/django/myvenv/lib64/python3.6/site-packages/django/template/loader.py", line 67, in render_to_string
    template = get_template(template_name, using=using)
  File "/home/cloud/django/myvenv/lib64/python3.6/site-packages/django/template/loader.py", line 21, in get_template
    return engine.get_template(template_name)
  File "/home/cloud/django/myvenv/lib64/python3.6/site-packages/django/template/backends/django.py", line 39, in get_template
    return Template(self.engine.get_template(template_name), self)
  File "/home/cloud/django/myvenv/lib64/python3.6/site-packages/django/template/engine.py", line 160, in get_template
    template, origin = self.find_template(template_name)
  File "/home/cloud/django/myvenv/lib64/python3.6/site-packages/django/template/engine.py", line 134, in find_template
    name, template_dirs=dirs, skip=skip,
  File "/home/cloud/django/myvenv/lib64/python3.6/site-packages/django/template/loaders/base.py", line 44, in get_template
    contents, origin, origin.template_name, self.engine,
  File "/home/cloud/django/myvenv/lib64/python3.6/site-packages/django/template/base.py", line 191, in __init__
    self.nodelist = self.compile_nodelist()
  File "/home/cloud/django/myvenv/lib64/python3.6/site-packages/django/template/base.py", line 233, in compile_nodelist
    return parser.parse()
  File "/home/cloud/django/myvenv/lib64/python3.6/site-packages/django/template/base.py", line 518, in parse
    raise self.error(token, e)
  File "/home/cloud/django/myvenv/lib64/python3.6/site-packages/django/template/base.py", line 516, in parse
    compiled_result = compile_func(self, token)
  File "/home/cloud/django/myvenv/lib64/python3.6/site-packages/django/template/loader_tags.py", line 301, in do_extends
    raise TemplateSyntaxError("'%s' cannot appear more than once in the same template" % bits[0])
django.template.exceptions.TemplateSyntaxError: 'extends' cannot appear more than once in the same template
[17/Jul/2017 08:13:43] "GET / HTTP/1.1" 500 120850
[17/Jul/2017 08:13:52] "GET / HTTP/1.1" 200 862
[17/Jul/2017 08:13:52] "GET /static/css/blog.css HTTP/1.1" 304 0
[17/Jul/2017 08:13:55] "GET / HTTP/1.1" 200 862
[17/Jul/2017 08:13:55] "GET /static/css/blog.css HTTP/1.1" 304 0
Performing system checks...

System check identified no issues (0 silenced).
July 17, 2017 - 08:13:22
Django version 1.10.7, using settings 'mysite.settings'
Starting development server at http://192.168.29.87:8000/
Quit the server with CONTROL-C.
[17/Jul/2017 08:19:28] "GET / HTTP/1.1" 200 862
[17/Jul/2017 08:19:28] "GET /static/css/blog.css HTTP/1.1" 304 0
Performing system checks...

System check identified no issues (0 silenced).
July 17, 2017 - 08:16:25
Django version 1.10.7, using settings 'mysite.settings'
Starting development server at http://192.168.29.87:8000/
Quit the server with CONTROL-C.
[17/Jul/2017 08:20:27] "GET / HTTP/1.1" 200 862
[17/Jul/2017 08:20:27] "GET /static/css/blog.css HTTP/1.1" 304 0
[17/Jul/2017 08:20:29] "GET / HTTP/1.1" 200 862
Performing system checks...

System check identified no issues (0 silenced).
July 17, 2017 - 08:20:26
Django version 1.10.7, using settings 'mysite.settings'
Starting development server at http://192.168.29.87:8000/
Quit the server with CONTROL-C.
Unhandled exception in thread started by <function check_errors.<locals>.wrapper at 0x7fd304888d08>
Traceback (most recent call last):
  File "/home/cloud/django/myvenv/lib64/python3.6/site-packages/django/utils/autoreload.py", line 226, in wrapper
    fn(*args, **kwargs)
  File "/home/cloud/django/myvenv/lib64/python3.6/site-packages/django/core/management/commands/runserver.py", line 121, in inner_run
    self.check(display_num_errors=True)
  File "/home/cloud/django/myvenv/lib64/python3.6/site-packages/django/core/management/base.py", line 374, in check
    include_deployment_checks=include_deployment_checks,
  File "/home/cloud/django/myvenv/lib64/python3.6/site-packages/django/core/management/base.py", line 361, in _run_checks
    return checks.run_checks(**kwargs)
  File "/home/cloud/django/myvenv/lib64/python3.6/site-packages/django/core/checks/registry.py", line 81, in run_checks
    new_errors = check(app_configs=app_configs)
  File "/home/cloud/django/myvenv/lib64/python3.6/site-packages/django/core/checks/urls.py", line 14, in check_url_config
    return check_resolver(resolver)
  File "/home/cloud/django/myvenv/lib64/python3.6/site-packages/django/core/checks/urls.py", line 24, in check_resolver
    for pattern in resolver.url_patterns:
  File "/home/cloud/django/myvenv/lib64/python3.6/site-packages/django/utils/functional.py", line 35, in __get__
    res = instance.__dict__[self.name] = self.func(instance)
  File "/home/cloud/django/myvenv/lib64/python3.6/site-packages/django/urls/resolvers.py", line 313, in url_patterns
    patterns = getattr(self.urlconf_module, "urlpatterns", self.urlconf_module)
  File "/home/cloud/django/myvenv/lib64/python3.6/site-packages/django/utils/functional.py", line 35, in __get__
    res = instance.__dict__[self.name] = self.func(instance)
  File "/home/cloud/django/myvenv/lib64/python3.6/site-packages/django/urls/resolvers.py", line 306, in urlconf_module
    return import_module(self.urlconf_name)
  File "/usr/lib64/python3.6/importlib/__init__.py", line 126, in import_module
    return _bootstrap._gcd_import(name[level:], package, level)
  File "<frozen importlib._bootstrap>", line 978, in _gcd_import
  File "<frozen importlib._bootstrap>", line 961, in _find_and_load
  File "<frozen importlib._bootstrap>", line 950, in _find_and_load_unlocked
  File "<frozen importlib._bootstrap>", line 655, in _load_unlocked
  File "<frozen importlib._bootstrap_external>", line 678, in exec_module
  File "<frozen importlib._bootstrap>", line 205, in _call_with_frames_removed
  File "/home/cloud/django/mysite/urls.py", line 21, in <module>
    url(r'', include('blog.urls')),
  File "/home/cloud/django/myvenv/lib64/python3.6/site-packages/django/conf/urls/__init__.py", line 50, in include
    urlconf_module = import_module(urlconf_module)
  File "/usr/lib64/python3.6/importlib/__init__.py", line 126, in import_module
    return _bootstrap._gcd_import(name[level:], package, level)
  File "<frozen importlib._bootstrap>", line 978, in _gcd_import
  File "<frozen importlib._bootstrap>", line 961, in _find_and_load
  File "<frozen importlib._bootstrap>", line 950, in _find_and_load_unlocked
  File "<frozen importlib._bootstrap>", line 655, in _load_unlocked
  File "<frozen importlib._bootstrap_external>", line 678, in exec_module
  File "<frozen importlib._bootstrap>", line 205, in _call_with_frames_removed
  File "/home/cloud/django/blog/urls.py", line 6, in <module>
    url(r'^post/(?P<pk>\d+)/$', views.post_detail, name='post_detail'),
AttributeError: module 'blog.views' has no attribute 'post_detail'
Performing system checks...

Internal Server Error: /
Traceback (most recent call last):
  File "/home/cloud/django/myvenv/lib64/python3.6/site-packages/django/core/handlers/exception.py", line 42, in inner
    response = get_response(request)
  File "/home/cloud/django/myvenv/lib64/python3.6/site-packages/django/core/handlers/base.py", line 187, in _get_response
    response = self.process_exception_by_middleware(e, request)
  File "/home/cloud/django/myvenv/lib64/python3.6/site-packages/django/core/handlers/base.py", line 185, in _get_response
    response = wrapped_callback(request, *callback_args, **callback_kwargs)
  File "/home/cloud/django/blog/views.py", line 8, in post_list
    return render(request, 'blog/post_list.html', {'posts': posts})
  File "/home/cloud/django/myvenv/lib64/python3.6/site-packages/django/shortcuts.py", line 30, in render
    content = loader.render_to_string(template_name, context, request, using=using)
  File "/home/cloud/django/myvenv/lib64/python3.6/site-packages/django/template/loader.py", line 68, in render_to_string
    return template.render(context, request)
  File "/home/cloud/django/myvenv/lib64/python3.6/site-packages/django/template/backends/django.py", line 66, in render
    return self.template.render(context)
  File "/home/cloud/django/myvenv/lib64/python3.6/site-packages/django/template/base.py", line 208, in render
    return self._render(context)
  File "/home/cloud/django/myvenv/lib64/python3.6/site-packages/django/template/base.py", line 199, in _render
    return self.nodelist.render(context)
  File "/home/cloud/django/myvenv/lib64/python3.6/site-packages/django/template/base.py", line 994, in render
    bit = node.render_annotated(context)
  File "/home/cloud/django/myvenv/lib64/python3.6/site-packages/django/template/base.py", line 961, in render_annotated
    return self.render(context)
  File "/home/cloud/django/myvenv/lib64/python3.6/site-packages/django/template/loader_tags.py", line 174, in render
    return compiled_parent._render(context)
  File "/home/cloud/django/myvenv/lib64/python3.6/site-packages/django/template/base.py", line 199, in _render
    return self.nodelist.render(context)
  File "/home/cloud/django/myvenv/lib64/python3.6/site-packages/django/template/base.py", line 994, in render
    bit = node.render_annotated(context)
  File "/home/cloud/django/myvenv/lib64/python3.6/site-packages/django/template/base.py", line 961, in render_annotated
    return self.render(context)
  File "/home/cloud/django/myvenv/lib64/python3.6/site-packages/django/template/loader_tags.py", line 70, in render
    result = block.nodelist.render(context)
  File "/home/cloud/django/myvenv/lib64/python3.6/site-packages/django/template/base.py", line 994, in render
    bit = node.render_annotated(context)
  File "/home/cloud/django/myvenv/lib64/python3.6/site-packages/django/template/base.py", line 961, in render_annotated
    return self.render(context)
  File "/home/cloud/django/myvenv/lib64/python3.6/site-packages/django/template/defaulttags.py", line 439, in render
    url = reverse(view_name, args=args, kwargs=kwargs, current_app=current_app)
  File "/home/cloud/django/myvenv/lib64/python3.6/site-packages/django/urls/base.py", line 91, in reverse
    return force_text(iri_to_uri(resolver._reverse_with_prefix(view, prefix, *args, **kwargs)))
  File "/home/cloud/django/myvenv/lib64/python3.6/site-packages/django/urls/resolvers.py", line 392, in _reverse_with_prefix
    (lookup_view_s, args, kwargs, len(patterns), patterns)
django.urls.exceptions.NoReverseMatch: Reverse for 'post_detail' with arguments '()' and keyword arguments '{'pk': ''}' not found. 0 pattern(s) tried: []
[17/Jul/2017 08:21:29] "GET / HTTP/1.1" 500 147032
[17/Jul/2017 08:21:51] "GET / HTTP/1.1" 200 863
[17/Jul/2017 08:21:51] "GET /static/css/blog.css HTTP/1.1" 304 0
[17/Jul/2017 08:23:01] "GET / HTTP/1.1" 200 862
[17/Jul/2017 08:23:01] "GET /static/css/blog.css HTTP/1.1" 304 0
[17/Jul/2017 08:23:30] "GET / HTTP/1.1" 200 1000
[17/Jul/2017 08:23:30] "GET /static/css/blog.css HTTP/1.1" 304 0
Performing system checks...

System check identified no issues (0 silenced).
July 17, 2017 - 08:22:59
Django version 1.10.7, using settings 'mysite.settings'
Starting development server at http://192.168.29.87:8000/
Quit the server with CONTROL-C.
Performing system checks...

System check identified no issues (0 silenced).
July 17, 2017 - 08:24:02
Django version 1.10.7, using settings 'mysite.settings'
Starting development server at http://192.168.29.87:8000/
Quit the server with CONTROL-C.
Performing system checks...

System check identified no issues (0 silenced).
July 17, 2017 - 08:24:08
Django version 1.10.7, using settings 'mysite.settings'
Starting development server at http://192.168.29.87:8000/
Quit the server with CONTROL-C.
[17/Jul/2017 08:24:15] "GET / HTTP/1.1" 200 1001
[17/Jul/2017 08:24:15] "GET /static/css/blog.css HTTP/1.1" 304 0
Internal Server Error: /post/1/
Traceback (most recent call last):
  File "/home/cloud/django/myvenv/lib64/python3.6/site-packages/django/core/handlers/exception.py", line 42, in inner
    response = get_response(request)
  File "/home/cloud/django/myvenv/lib64/python3.6/site-packages/django/core/handlers/base.py", line 187, in _get_response
    response = self.process_exception_by_middleware(e, request)
  File "/home/cloud/django/myvenv/lib64/python3.6/site-packages/django/core/handlers/base.py", line 185, in _get_response
    response = wrapped_callback(request, *callback_args, **callback_kwargs)
  File "/home/cloud/django/blog/views.py", line 12, in post_detail
    return render(request, 'blog/post_detail.html', {'posts': posts})
NameError: name 'posts' is not defined
[17/Jul/2017 08:24:17] "GET /post/1/ HTTP/1.1" 500 63203
Internal Server Error: /post/1/
Traceback (most recent call last):
  File "/home/cloud/django/myvenv/lib64/python3.6/site-packages/django/core/handlers/exception.py", line 42, in inner
    response = get_response(request)
  File "/home/cloud/django/myvenv/lib64/python3.6/site-packages/django/core/handlers/base.py", line 187, in _get_response
    response = self.process_exception_by_middleware(e, request)
  File "/home/cloud/django/myvenv/lib64/python3.6/site-packages/django/core/handlers/base.py", line 185, in _get_response
    response = wrapped_callback(request, *callback_args, **callback_kwargs)
  File "/home/cloud/django/blog/views.py", line 12, in post_detail
    return render(request, 'blog/post_detail.html', {'posts': posts})
NameError: name 'posts' is not defined
[17/Jul/2017 08:24:54] "GET /post/1/ HTTP/1.1" 500 63203
[17/Jul/2017 08:24:58] "GET / HTTP/1.1" 200 1001
[17/Jul/2017 08:24:59] "GET / HTTP/1.1" 200 1001
Internal Server Error: /post/1/
Traceback (most recent call last):
  File "/home/cloud/django/myvenv/lib64/python3.6/site-packages/django/core/handlers/exception.py", line 42, in inner
    response = get_response(request)
  File "/home/cloud/django/myvenv/lib64/python3.6/site-packages/django/core/handlers/base.py", line 187, in _get_response
    response = self.process_exception_by_middleware(e, request)
  File "/home/cloud/django/myvenv/lib64/python3.6/site-packages/django/core/handlers/base.py", line 185, in _get_response
    response = wrapped_callback(request, *callback_args, **callback_kwargs)
  File "/home/cloud/django/blog/views.py", line 12, in post_detail
    return render(request, 'blog/post_detail.html', {'posts': posts})
NameError: name 'posts' is not defined
[17/Jul/2017 08:25:02] "GET /post/1/ HTTP/1.1" 500 63203
Performing system checks...

System check identified no issues (0 silenced).
July 17, 2017 - 08:24:12
Django version 1.10.7, using settings 'mysite.settings'
Starting development server at http://192.168.29.87:8000/
Quit the server with CONTROL-C.
[17/Jul/2017 08:25:15] "GET /post/1/ HTTP/1.1" 200 977
[17/Jul/2017 08:25:15] "GET /static/css/blog.css HTTP/1.1" 304 0
[17/Jul/2017 08:25:21] "GET / HTTP/1.1" 200 1001
[17/Jul/2017 09:09:48] "GET / HTTP/1.1" 200 1001
[17/Jul/2017 09:09:49] "GET /static/css/blog.css HTTP/1.1" 200 794
[18/Jul/2017 01:05:08] "GET / HTTP/1.1" 200 1001
[18/Jul/2017 01:05:08] "GET /static/css/blog.css HTTP/1.1" 200 794
Not Found: /favicon.ico
[18/Jul/2017 01:05:09] "GET /favicon.ico HTTP/1.1" 404 2301
[18/Jul/2017 07:52:25] "GET / HTTP/1.1" 200 1001
[18/Jul/2017 07:52:25] "GET /static/css/blog.css HTTP/1.1" 304 0
[18/Jul/2017 07:52:25] "GET /static/css/blog.css HTTP/1.1" 304 0
[19/Jul/2017 08:04:51] "GET / HTTP/1.1" 200 1001
[19/Jul/2017 08:04:51] "GET /static/css/blog.css HTTP/1.1" 304 0
Not Found: /favicon.ico
[19/Jul/2017 08:04:51] "GET /favicon.ico HTTP/1.1" 404 2301
[19/Jul/2017 08:05:34] "GET /post/1/ HTTP/1.1" 200 977
[19/Jul/2017 08:05:39] "GET / HTTP/1.1" 200 1001
Internal Server Error: /
Traceback (most recent call last):
  File "/home/cloud/django/myvenv/lib64/python3.6/site-packages/django/core/handlers/exception.py", line 42, in inner
    response = get_response(request)
  File "/home/cloud/django/myvenv/lib64/python3.6/site-packages/django/core/handlers/base.py", line 187, in _get_response
    response = self.process_exception_by_middleware(e, request)
  File "/home/cloud/django/myvenv/lib64/python3.6/site-packages/django/core/handlers/base.py", line 185, in _get_response
    response = wrapped_callback(request, *callback_args, **callback_kwargs)
  File "/home/cloud/django/blog/views.py", line 8, in post_list
    return render(request, 'blog/post_list.html', {'posts': posts})
  File "/home/cloud/django/myvenv/lib64/python3.6/site-packages/django/shortcuts.py", line 30, in render
    content = loader.render_to_string(template_name, context, request, using=using)
  File "/home/cloud/django/myvenv/lib64/python3.6/site-packages/django/template/loader.py", line 68, in render_to_string
    return template.render(context, request)
  File "/home/cloud/django/myvenv/lib64/python3.6/site-packages/django/template/backends/django.py", line 66, in render
    return self.template.render(context)
  File "/home/cloud/django/myvenv/lib64/python3.6/site-packages/django/template/base.py", line 208, in render
    return self._render(context)
  File "/home/cloud/django/myvenv/lib64/python3.6/site-packages/django/template/base.py", line 199, in _render
    return self.nodelist.render(context)
  File "/home/cloud/django/myvenv/lib64/python3.6/site-packages/django/template/base.py", line 994, in render
    bit = node.render_annotated(context)
  File "/home/cloud/django/myvenv/lib64/python3.6/site-packages/django/template/base.py", line 961, in render_annotated
    return self.render(context)
  File "/home/cloud/django/myvenv/lib64/python3.6/site-packages/django/template/loader_tags.py", line 174, in render
    return compiled_parent._render(context)
  File "/home/cloud/django/myvenv/lib64/python3.6/site-packages/django/template/base.py", line 199, in _render
    return self.nodelist.render(context)
  File "/home/cloud/django/myvenv/lib64/python3.6/site-packages/django/template/base.py", line 994, in render
    bit = node.render_annotated(context)
  File "/home/cloud/django/myvenv/lib64/python3.6/site-packages/django/template/base.py", line 961, in render_annotated
    return self.render(context)
  File "/home/cloud/django/myvenv/lib64/python3.6/site-packages/django/template/defaulttags.py", line 439, in render
    url = reverse(view_name, args=args, kwargs=kwargs, current_app=current_app)
  File "/home/cloud/django/myvenv/lib64/python3.6/site-packages/django/urls/base.py", line 91, in reverse
    return force_text(iri_to_uri(resolver._reverse_with_prefix(view, prefix, *args, **kwargs)))
  File "/home/cloud/django/myvenv/lib64/python3.6/site-packages/django/urls/resolvers.py", line 392, in _reverse_with_prefix
    (lookup_view_s, args, kwargs, len(patterns), patterns)
django.urls.exceptions.NoReverseMatch: Reverse for 'post_new' with arguments '()' and keyword arguments '{}' not found. 0 pattern(s) tried: []
[19/Jul/2017 08:07:46] "GET / HTTP/1.1" 500 131948
Performing system checks...

System check identified no issues (0 silenced).
July 17, 2017 - 08:25:14
Django version 1.10.7, using settings 'mysite.settings'
Starting development server at http://192.168.29.87:8000/
Quit the server with CONTROL-C.
Unhandled exception in thread started by <function check_errors.<locals>.wrapper at 0x7f84ce5e0d08>
Traceback (most recent call last):
  File "/home/cloud/django/myvenv/lib64/python3.6/site-packages/django/utils/autoreload.py", line 226, in wrapper
    fn(*args, **kwargs)
  File "/home/cloud/django/myvenv/lib64/python3.6/site-packages/django/core/management/commands/runserver.py", line 121, in inner_run
    self.check(display_num_errors=True)
  File "/home/cloud/django/myvenv/lib64/python3.6/site-packages/django/core/management/base.py", line 374, in check
    include_deployment_checks=include_deployment_checks,
  File "/home/cloud/django/myvenv/lib64/python3.6/site-packages/django/core/management/base.py", line 361, in _run_checks
    return checks.run_checks(**kwargs)
  File "/home/cloud/django/myvenv/lib64/python3.6/site-packages/django/core/checks/registry.py", line 81, in run_checks
    new_errors = check(app_configs=app_configs)
  File "/home/cloud/django/myvenv/lib64/python3.6/site-packages/django/core/checks/urls.py", line 14, in check_url_config
    return check_resolver(resolver)
  File "/home/cloud/django/myvenv/lib64/python3.6/site-packages/django/core/checks/urls.py", line 24, in check_resolver
    for pattern in resolver.url_patterns:
  File "/home/cloud/django/myvenv/lib64/python3.6/site-packages/django/utils/functional.py", line 35, in __get__
    res = instance.__dict__[self.name] = self.func(instance)
  File "/home/cloud/django/myvenv/lib64/python3.6/site-packages/django/urls/resolvers.py", line 313, in url_patterns
    patterns = getattr(self.urlconf_module, "urlpatterns", self.urlconf_module)
  File "/home/cloud/django/myvenv/lib64/python3.6/site-packages/django/utils/functional.py", line 35, in __get__
    res = instance.__dict__[self.name] = self.func(instance)
  File "/home/cloud/django/myvenv/lib64/python3.6/site-packages/django/urls/resolvers.py", line 306, in urlconf_module
    return import_module(self.urlconf_name)
  File "/usr/lib64/python3.6/importlib/__init__.py", line 126, in import_module
    return _bootstrap._gcd_import(name[level:], package, level)
  File "<frozen importlib._bootstrap>", line 978, in _gcd_import
  File "<frozen importlib._bootstrap>", line 961, in _find_and_load
  File "<frozen importlib._bootstrap>", line 950, in _find_and_load_unlocked
  File "<frozen importlib._bootstrap>", line 655, in _load_unlocked
  File "<frozen importlib._bootstrap_external>", line 678, in exec_module
  File "<frozen importlib._bootstrap>", line 205, in _call_with_frames_removed
  File "/home/cloud/django/mysite/urls.py", line 21, in <module>
    url(r'', include('blog.urls')),
  File "/home/cloud/django/myvenv/lib64/python3.6/site-packages/django/conf/urls/__init__.py", line 50, in include
    urlconf_module = import_module(urlconf_module)
  File "/usr/lib64/python3.6/importlib/__init__.py", line 126, in import_module
    return _bootstrap._gcd_import(name[level:], package, level)
  File "<frozen importlib._bootstrap>", line 978, in _gcd_import
  File "<frozen importlib._bootstrap>", line 961, in _find_and_load
  File "<frozen importlib._bootstrap>", line 950, in _find_and_load_unlocked
  File "<frozen importlib._bootstrap>", line 655, in _load_unlocked
  File "<frozen importlib._bootstrap_external>", line 678, in exec_module
  File "<frozen importlib._bootstrap>", line 205, in _call_with_frames_removed
  File "/home/cloud/django/blog/urls.py", line 7, in <module>
    url(r'^post/new/$', views.post_new, name='post_new'),
AttributeError: module 'blog.views' has no attribute 'post_new'
Performing system checks...

[19/Jul/2017 08:09:06] "GET / HTTP/1.1" 200 1095
[19/Jul/2017 08:09:08] "GET /post/new/ HTTP/1.1" 200 1397
[19/Jul/2017 08:09:17] "POST /post/new/ HTTP/1.1" 200 1397
[19/Jul/2017 08:09:19] "GET / HTTP/1.1" 200 1095
[19/Jul/2017 08:09:20] "GET / HTTP/1.1" 200 1095
Performing system checks...

System check identified no issues (0 silenced).
July 19, 2017 - 08:08:39
Django version 1.10.7, using settings 'mysite.settings'
Starting development server at http://192.168.29.87:8000/
Quit the server with CONTROL-C.
[19/Jul/2017 08:10:27] "GET / HTTP/1.1" 200 1095
[19/Jul/2017 08:10:28] "GET /post/new/ HTTP/1.1" 200 1397
Internal Server Error: /post/new/
Traceback (most recent call last):
  File "/home/cloud/django/myvenv/lib64/python3.6/site-packages/django/core/handlers/exception.py", line 42, in inner
    response = get_response(request)
  File "/home/cloud/django/myvenv/lib64/python3.6/site-packages/django/core/handlers/base.py", line 187, in _get_response
    response = self.process_exception_by_middleware(e, request)
  File "/home/cloud/django/myvenv/lib64/python3.6/site-packages/django/core/handlers/base.py", line 185, in _get_response
    response = wrapped_callback(request, *callback_args, **callback_kwargs)
  File "/home/cloud/django/blog/views.py", line 13, in post_new
    post.author = request.user
  File "/home/cloud/django/myvenv/lib64/python3.6/site-packages/django/db/models/fields/related_descriptors.py", line 211, in __set__
    self.field.remote_field.model._meta.object_name,
ValueError: Cannot assign "<SimpleLazyObject: <django.contrib.auth.models.AnonymousUser object at 0x7f3c5479ab00>>": "Post.author" must be a "User" instance.
[19/Jul/2017 08:10:30] "POST /post/new/ HTTP/1.1" 500 71266
[19/Jul/2017 08:11:30] "GET /admin HTTP/1.1" 301 0
[19/Jul/2017 08:11:30] "GET /admin/ HTTP/1.1" 302 0
[19/Jul/2017 08:11:30] "GET /admin/login/?next=/admin/ HTTP/1.1" 200 1653
[19/Jul/2017 08:11:30] "GET /static/admin/css/base.css HTTP/1.1" 200 15937
[19/Jul/2017 08:11:30] "GET /static/admin/css/login.css HTTP/1.1" 200 1203
[19/Jul/2017 08:11:30] "GET /static/admin/css/fonts.css HTTP/1.1" 200 423
[19/Jul/2017 08:11:30] "GET /static/admin/fonts/Roboto-Regular-webfont.woff HTTP/1.1" 200 80304
[19/Jul/2017 08:11:30] "GET /static/admin/fonts/Roboto-Light-webfont.woff HTTP/1.1" 200 81348
[19/Jul/2017 08:11:34] "POST /admin/login/?next=/admin/ HTTP/1.1" 200 1816
[19/Jul/2017 08:11:34] "GET /static/admin/fonts/Roboto-Bold-webfont.woff HTTP/1.1" 200 82564
[19/Jul/2017 08:11:37] "POST /admin/login/?next=/admin/ HTTP/1.1" 200 1814
[19/Jul/2017 08:11:43] "POST /admin/login/?next=/admin/ HTTP/1.1" 200 1814
[19/Jul/2017 08:11:52] "POST /admin/login/?next=/admin/ HTTP/1.1" 302 0
[19/Jul/2017 08:11:52] "GET /admin/ HTTP/1.1" 200 3375
[19/Jul/2017 08:11:52] "GET /static/admin/css/dashboard.css HTTP/1.1" 200 434
[19/Jul/2017 08:11:52] "GET /static/admin/img/icon-addlink.svg HTTP/1.1" 200 331
[19/Jul/2017 08:11:52] "GET /static/admin/img/icon-changelink.svg HTTP/1.1" 200 380
[19/Jul/2017 08:12:02] "GET / HTTP/1.1" 200 1095
[19/Jul/2017 08:12:03] "GET /post/new/ HTTP/1.1" 200 1397
[19/Jul/2017 08:12:09] "POST /post/new/ HTTP/1.1" 302 0
[19/Jul/2017 08:12:09] "GET /post/2/ HTTP/1.1" 200 1084
Not Found: /post/
[19/Jul/2017 08:12:16] "GET /post/ HTTP/1.1" 404 2458
[19/Jul/2017 08:12:19] "GET / HTTP/1.1" 200 1320
[19/Jul/2017 08:12:20] "GET /post/2/ HTTP/1.1" 200 1084
[19/Jul/2017 08:12:22] "GET / HTTP/1.1" 200 1320
